<?xml version="1.0" ?>
<robot name="scara" xmlns:xacro="http://www.ros.org/wiki/xacro">

<xacro:include filename="$(find scara_description_pkg)/urdf/materials.xacro" />
<xacro:include filename="$(find scara_description_pkg)/urdf/scara.trans" />
<xacro:include filename="$(find scara_description_pkg)/urdf/scara.gazebo" />

<link name="base_link">
  <inertial>
    <origin rpy="0.0 0.0 0.0" xyz="0.0 0.0 0.0"/>
    <mass value="0.5"/>
    <inertia ixx="0.0" ixy="0.0" ixz="0.0" iyy="0.0" iyz="0.0" izz="0.0"/>
  </inertial>
  <visual>
    <origin rpy="0.0 0.0 0.0" xyz="0.0 0.0 0.0"/>
    <geometry>
      <mesh filename="package://scara_description_pkg/meshes/base_link.stl" scale="0.001 0.001 0.001"/>
    </geometry>
    <material name="gray"/>
  </visual>
  <collision>
    <origin rpy="0.0 0.0 0.0" xyz="0.0 0.0 0.0"/>
    <geometry>
      <mesh filename="package://scara_description_pkg/meshes/base_link.stl" scale="0.001 0.001 0.001"/>
    </geometry>
  </collision>
</link>

<link name="link1">
  <inertial>
    <origin rpy="0.0 0.0 0.0" xyz="0.0 0.0 0.000"/>
    <mass value="0.2"/>
    <inertia ixx="0.0" ixy="0.0" ixz="0.0" iyy="0.0" iyz="0.0" izz="0.0"/>
  </inertial>
  <visual>
    <origin rpy="0.0 0.0 0.0" xyz="0.0 0.0 0.0"/>
    <geometry>
      <mesh filename="package://scara_description_pkg/meshes/link1.stl" scale="0.001 0.001 0.001"/>
    </geometry>
    <material name="red"/>
  </visual>
  <collision>
    <origin rpy="0.0 0.0 0.0" xyz="0.0 0.0 0.0"/>
    <geometry>
      <mesh filename="package://scara_description_pkg/meshes/link1.stl" scale="0.001 0.001 0.001"/>
    </geometry>
  </collision>
</link>

<link name="link2">
  <inertial>
    <origin rpy="0.0 0.0 0.0" xyz="0.16015 0.0 0.0168"/>
    <mass value="0.18"/>
    <inertia ixx="0.0" ixy="0.0" ixz="0.0" iyy="0.0" iyz="0.0" izz="0.0"/>
  </inertial>
  <visual>
    <origin rpy="0.0 0.0 0.0" xyz="0.0 0.0 0.0"/>
    <geometry>
      <mesh filename="package://scara_description_pkg/meshes/link2.stl" scale="0.001 0.001 0.001"/>
    </geometry>
    <material name="blue"/>
  </visual>
  <collision>
    <origin rpy="0.0 0.0 0.0" xyz="0.0 0.0 0.0"/>
    <geometry>
      <mesh filename="package://scara_description_pkg/meshes/link2.stl" scale="0.001 0.001 0.001"/>
    </geometry>
  </collision>
</link>

<link name="link3">
  <inertial>
    <origin rpy="0.0 0.0 0.0" xyz="0.18265 0.0 0.0317"/>
    <mass value="0.08"/>
    <inertia ixx="0.0" ixy="0.0" ixz="0.0" iyy="0.0" iyz="0.0" izz="0.0"/>
  </inertial>
  <visual>
    <origin rpy="0.0 0.0 0.0" xyz="0.0 0.0 0.0"/>
    <geometry>
      <mesh filename="package://scara_description_pkg/meshes/link3.stl" scale="0.001 0.001 0.001"/>
    </geometry>
    <material name="green"/>
  </visual>
  <collision>
    <origin rpy="0.0 0.0 0.0" xyz="0.0 0.0 0.0"/>
    <geometry>
      <mesh filename="package://scara_description_pkg/meshes/link3.stl" scale="0.001 0.001 0.001"/>
    </geometry>
  </collision>
</link>

<link name="gripper">
  <inertial>
    <origin rpy="0.0 0.0 0.0" xyz="0.0 0.0 0.0"/>
    <mass value="0.02"/>
    <inertia ixx="0.0" ixy="0.0" ixz="0.0" iyy="0.0" iyz="0.0" izz="0.0"/>
  </inertial>
  <visual>
    <origin rpy="0.0 0.0 0.0" xyz="0.0 0.0 0"/>
    <geometry>
      <cylinder length="0.004" radius="0.008"/>
    </geometry>
    <material name="red"/>
  </visual>
</link>

<joint name="Slider1" type="prismatic">
  <origin rpy="0.0 0.0 0.0" xyz="0.0 0.0 0.0"/>
  <parent link="base_link"/>
  <child link="link1"/>
  <axis xyz="0.0 0.0 1.0"/>
  <limit effort="100" lower="0.08" upper="0.310" velocity="100"/>
</joint>

<joint name="Rev2" type="revolute">
  <origin rpy="0.0 0.0 0.0" xyz="0.16015 0.0 0.0168"/>
  <parent link="link1"/>
  <child link="link2"/>
  <axis xyz="0.0 0.0 1.0"/>
  <limit effort="100" lower="-2.094395" upper="2.094395" velocity="100"/>
</joint>

<joint name="Rev3" type="revolute">
  <origin rpy="0.0 0.0 0.0" xyz="0.18265 0.0 -0.0317"/>
  <parent link="link2"/>
  <child link="link3"/>
  <axis xyz="0.0 0.0 1.0"/>
  <limit effort="100" lower="0" upper="2.443461" velocity="100"/>
</joint>

<joint name="Fixed4" type="fixed">
  <origin rpy="0.0 0.0 0.0" xyz="0.157 0.0 -0.09"/>
  <parent link="link3"/>
  <child link="gripper"/>
</joint>

</robot>
